Workbook

Sheet Lista Unificada
A1: Dotación consultorio de medicina general — lista unificada para cotización
A2: Valores aproximados en pesos colombianos (COP), mercado colombiano 2026. Incluye la lista del Dr. Sergio Durán (PDF “Dotación necesaria para los consultorios”). Celdas amarillas = ítems adicionales.
A4: # | B4: Categoría | C4: Implemento | D4: Especificación | E4: Cantidad | F4: Unidad | G4: Valor unitario aprox. (COP) | H4: Valor total aprox. (COP) | I4: Prioridad | J4: Fuente | K4: Observaciones
A5: 1 | B5: Equipos biomédicos | C5: Tensiómetro aneroide adulto | D5: Con brazalete adulto estándar, calibrado | E5: 1 | F5: Unidad | G5: 150000 | H5: =IF(OR(E5="",G5=""),"",E5*G5) | I5: Obligatorio | J5: Dotación básica | K5: Requiere hoja de vida y plan de calibración anual
A6: 2 | B6: Equipos biomédicos | C6: Brazaletes adicionales | D6: Pediátrico y adulto obeso | E6: 2 | F6: Unidad | G6: 60000 | H6: =IF(OR(E6="",G6=""),"",E6*G6) | I6: Obligatorio | J6: Dotación básica
A7: 3 | B7: Equipos biomédicos | C7: Tensiómetro digital de brazo | D7: Automático, validado clínicamente | E7: 1 | F7: Unidad | G7: 250000 | H7: =IF(OR(E7="",G7=""),"",E7*G7) | I7: Recomendado | J7: Dotación básica
A8: 4 | B8: Equipos biomédicos | C8: Fonendoscopio | D8: Doble campana, tipo Littmann Classic III o similar | E8: 1 | F8: Unidad | G8: 650000 | H8: =IF(OR(E8="",G8=""),"",E8*G8) | I8: Obligatorio | J8: Dotación básica | K8: Marcas genéricas desde ~150.000
A9: 5 | B9: Equipos biomédicos | C9: Equipo de órganos de los sentidos | D9: Otoscopio + oftalmoscopio portátil, halógeno/LED | E9: 1 | F9: Kit | G9: 1500000 | H9: =IF(OR(E9="",G9=""),"",E9*G9) | I9: Obligatorio | J9: Dotación básica | K9: Welch Allyn/Riester; versión de pared ~3.500.000
A10: 6 | B10: Equipos biomédicos | C10: Termómetro digital de contacto | D10: Punta flexible | E10: 2 | F10: Unidad | G10: 20000 | H10: =IF(OR(E10="",G10=""),"",E10*G10) | I10: Obligatorio | J10: Ambas | K10: Dr. Durán: 'Termómetro' (botiquín)
A11: 7 | B11: Equipos biomédicos | C11: Termómetro infrarrojo | D11: Frente, sin contacto | E11: 1 | F11: Unidad | G11: 120000 | H11: =IF(OR(E11="",G11=""),"",E11*G11) | I11: Recomendado | J11: Dotación básica
A12: 8 | B12: Equipos biomédicos | C12: Pulsioxímetro | D12: De dedo, adulto/pediátrico | E12: 1 | F12: Unidad | G12: 120000 | H12: =IF(OR(E12="",G12=""),"",E12*G12) | I12: Obligatorio | J12: Dotación básica
A13: 9 | B13: Equipos biomédicos | C13: Glucómetro | D13: Kit con lancetero | E13: 1 | F13: Kit | G13: 90000 | H13: =IF(OR(E13="",G13=""),"",E13*G13) | I13: Recomendado | J13: Dotación básica
A14: 10 | B14: Equipos biomédicos | C14: Báscula de pie con tallímetro | D14: Digital o mecánica, hasta 180 kg | E14: 1 | F14: Unidad | G14: 950000 | H14: =IF(OR(E14="",G14=""),"",E14*G14) | I14: Obligatorio | J14: Dotación básica
A15: 11 | B15: Equipos biomédicos | C15: Báscula pesabebés | D15: Digital, hasta 20 kg | E15: 1 | F15: Unidad | G15: 450000 | H15: =IF(OR(E15="",G15=""),"",E15*G15) | I15: Obligatorio | J15: Dotación básica | K15: Si se atiende población pediátrica
A16: 12 | B16: Equipos biomédicos | C16: Infantómetro | D16: Para medición en decúbito | E16: 1 | F16: Unidad | G16: 180000 | H16: =IF(OR(E16="",G16=""),"",E16*G16) | I16: Obligatorio | J16: Dotación básica | K16: Si se atiende población pediátrica
A17: 13 | B17: Equipos biomédicos | C17: Cinta métrica | D17: Inextensible, para perímetros | E17: 2 | F17: Unidad | G17: 15000 | H17: =IF(OR(E17="",G17=""),"",E17*G17) | I17: Obligatorio | J17: Dotación básica
A18: 14 | B18: Equipos biomédicos | C18: Martillo de reflejos | D18: Tipo Taylor | E18: 1 | F18: Unidad | G18: 25000 | H18: =IF(OR(E18="",G18=""),"",E18*G18) | I18: Obligatorio | J18: Dotación básica
A19: 15 | B19: Equipos biomédicos | C19: Diapasón | D19: 128 Hz | E19: 1 | F19: Unidad | G19: 60000 | H19: =IF(OR(E19="",G19=""),"",E19*G19) | I19: Recomendado | J19: Dotación básica
A20: 16 | B20: Equipos biomédicos | C20: Monofilamento 10 g | D20: Tamizaje pie diabético | E20: 1 | F20: Unidad | G20: 25000 | H20: =IF(OR(E20="",G20=""),"",E20*G20) | I20: Recomendado | J20: Dotación básica
A21: 17 | B21: Equipos biomédicos | C21: Linterna de diagnóstico | D21: LED, tipo lápiz | E21: 1 | F21: Unidad | G21: 40000 | H21: =IF(OR(E21="",G21=""),"",E21*G21) | I21: Obligatorio | J21: Dotación básica
A22: 18 | B22: Equipos biomédicos | C22: Tabla de Snellen | D22: Optotipos adulto/infantil | E22: 1 | F22: Unidad | G22: 30000 | H22: =IF(OR(E22="",G22=""),"",E22*G22) | I22: Obligatorio | J22: Dotación básica
A23: 19 | B23: Equipos biomédicos | C23: Negatoscopio | D23: 1 cuerpo, LED | E23: 1 | F23: Unidad | G23: 350000 | H23: =IF(OR(E23="",G23=""),"",E23*G23) | I23: Opcional | J23: Dotación básica
A24: 20 | B24: Equipos biomédicos | C24: Electrocardiógrafo | D24: 3 canales, con interpretación | E24: 1 | F24: Unidad | G24: 4500000 | H24: =IF(OR(E24="",G24=""),"",E24*G24) | I24: Opcional | J24: Dotación básica
A25: 21 | B25: Mobiliario clínico | C25: Camilla de examen | D25: Tapizado sanitario, cabecera graduable | E25: 1 | F25: Unidad | G25: 750000 | H25: =IF(OR(E25="",G25=""),"",E25*G25) | I25: Obligatorio | J25: Dotación básica
A26: 22 | B26: Mobiliario clínico | C26: Escalerilla | D26: 2 pasos, antideslizante | E26: 1 | F26: Unidad | G26: 180000 | H26: =IF(OR(E26="",G26=""),"",E26*G26) | I26: Obligatorio | J26: Dotación básica
A27: 23 | B27: Mobiliario clínico | C27: Lámpara de examen | D27: Cuello de cisne, LED, rodachinas | E27: 1 | F27: Unidad | G27: 450000 | H27: =IF(OR(E27="",G27=""),"",E27*G27) | I27: Obligatorio | J27: Dotación básica
A28: 24 | B28: Mobiliario clínico | C28: Mesa auxiliar / de Mayo | D28: Acero inoxidable | E28: 1 | F28: Unidad | G28: 350000 | H28: =IF(OR(E28="",G28=""),"",E28*G28) | I28: Recomendado | J28: Dotación básica
A29: 25 | B29: Mobiliario clínico | C29: Biombo | D29: 2-3 cuerpos, lavable | E29: 1 | F29: Unidad | G29: 450000 | H29: =IF(OR(E29="",G29=""),"",E29*G29) | I29: Obligatorio | J29: Dotación básica | K29: Privacidad del paciente
A30: 26 | B30: Mobiliario clínico | C30: Taburete giratorio | D30: Altura graduable, rodachinas | E30: 1 | F30: Unidad | G30: 250000 | H30: =IF(OR(E30="",G30=""),"",E30*G30) | I30: Recomendado | J30: Dotación básica
A31: 27 | B31: Mobiliario clínico | C31: Vitrina para insumos | D31: Metálica, puertas de vidrio | E31: 1 | F31: Unidad | G31: 800000 | H31: =IF(OR(E31="",G31=""),"",E31*G31) | I31: Recomendado | J31: Dotación básica
A32: 28 | B32: Mobiliario de oficina | C32: Escritorio | D32: Superficie lavable | E32: 1 | F32: Unidad | G32: 600000 | H32: =IF(OR(E32="",G32=""),"",E32*G32) | I32: Obligatorio | J32: Dotación básica
A33: 29 | B33: Mobiliario de oficina | C33: Silla ergonómica médico | D33: Con rodachinas | E33: 1 | F33: Unidad | G33: 450000 | H33: =IF(OR(E33="",G33=""),"",E33*G33) | I33: Obligatorio | J33: Dotación básica
A34: 30 | B34: Mobiliario de oficina | C34: Sillas paciente / acompañante | D34: Tapizado lavable | E34: 2 | F34: Unidad | G34: 150000 | H34: =IF(OR(E34="",G34=""),"",E34*G34) | I34: Obligatorio | J34: Dotación básica
A35: 31 | B35: Mobiliario de oficina | C35: Archivador | D35: 4 gavetas, con llave | E35: 1 | F35: Unidad | G35: 700000 | H35: =IF(OR(E35="",G35=""),"",E35*G35) | I35: Recomendado | J35: Dotación básica | K35: Custodia de documentos
A36: 32 | B36: Tecnología | C36: Computador | D36: Para historia clínica electrónica | E36: 1 | F36: Unidad | G36: 2800000 | H36: =IF(OR(E36="",G36=""),"",E36*G36) | I36: Obligatorio | J36: Dotación básica
A37: 33 | B37: Tecnología | C37: Impresora multifuncional | D37: Láser | E37: 1 | F37: Unidad | G37: 700000 | H37: =IF(OR(E37="",G37=""),"",E37*G37) | I37: Recomendado | J37: Dotación básica
A38: 34 | B38: Instrumental | C38: Equipo de pequeña cirugía | D38: Porta agujas, pinzas con/sin garra, tijeras, mango de bisturí | E38: 2 | F38: Kit | G38: 250000 | H38: =IF(OR(E38="",G38=""),"",E38*G38) | I38: Recomendado | J38: Dotación básica | K38: Si se realizan procedimientos menores
A39: 35 | B39: Instrumental | C39: Pinza de Kelly | D39: Recta/curva, 14 cm | E39: 2 | F39: Unidad | G39: 30000 | H39: =IF(OR(E39="",G39=""),"",E39*G39) | I39: Recomendado | J39: Dotación básica
A40: 36 | B40: Instrumental | C40: Riñonera | D40: Acero inoxidable | E40: 2 | F40: Unidad | G40: 35000 | H40: =IF(OR(E40="",G40=""),"",E40*G40) | I40: Obligatorio | J40: Dotación básica
A41: 37 | B41: Instrumental | C41: Bandeja con tapa | D41: Acero inoxidable | E41: 2 | F41: Unidad | G41: 90000 | H41: =IF(OR(E41="",G41=""),"",E41*G41) | I41: Recomendado | J41: Dotación básica
...

Sheet Resumen
A1: Resumen de la cotización
A3: Por categoría | B3: Valor aprox. (COP)
A4: Equipos biomédicos | B4: =SUMIFS('Lista Unificada'!$H$5:$H$104,'Lista Unificada'!$B$5:$B$104,A4)
A5: Mobiliario clínico | B5: =SUMIFS('Lista Unificada'!$H$5:$H$104,'Lista Unificada'!$B$5:$B$104,A5)
A6: Mobiliario de oficina | B6: =SUMIFS('Lista Unificada'!$H$5:$H$104,'Lista Unificada'!$B$5:$B$104,A6)
A7: Tecnología | B7: =SUMIFS('Lista Unificada'!$H$5:$H$104,'Lista Unificada'!$B$5:$B$104,A7)
A8: Instrumental | B8: =SUMIFS('Lista Unificada'!$H$5:$H$104,'Lista Unificada'!$B$5:$B$104,A8)
A9: Emergencias | B9: =SUMIFS('Lista Unificada'!$H$5:$H$104,'Lista Unificada'!$B$5:$B$104,A9)
A10: Bioseguridad y residuos | B10: =SUMIFS('Lista Unificada'!$H$5:$H$104,'Lista Unificada'!$B$5:$B$104,A10)
A11: Consumibles | B11: =SUMIFS('Lista Unificada'!$H$5:$H$104,'Lista Unificada'!$B$5:$B$104,A11)
A12: Atención de pacientes | B12: =SUMIFS('Lista Unificada'!$H$5:$H$104,'Lista Unificada'!$B$5:$B$104,A12)
A13: Papelería y oficina | B13: =SUMIFS('Lista Unificada'!$H$5:$H$104,'Lista Unificada'!$B$5:$B$104,A13)
A14: Aseo y baño | B14: =SUMIFS('Lista Unificada'!$H$5:$H$104,'Lista Unificada'!$B$5:$B$104,A14)
A15: Botiquín de primeros auxilios | B15: =SUMIFS('Lista Unificada'!$H$5:$H$104,'Lista Unificada'!$B$5:$B$104,A15)
A16: Otras categorías / sin clasificar | B16: ='Lista Unificada'!H105-SUM(B4:B15)
A17: TOTAL (1 consultorio) | B17: ='Lista Unificada'!H105
A18: Consultorios a dotar | B18: 1
A19: TOTAL GENERAL | B19: =B17*B18
A21: Por fuente | B21: Valor aprox. (COP)
A22: Dotación básica | B22: =SUMIFS('Lista Unificada'!$H$5:$H$104,'Lista Unificada'!$J$5:$J$104,A22)
A23: Dr. Sergio Durán | B23: =SUMIFS('Lista Unificada'!$H$5:$H$104,'Lista Unificada'!$J$5:$J$104,A23)
A24: Ambas | B24: =SUMIFS('Lista Unificada'!$H$5:$H$104,'Lista Unificada'!$J$5:$J$104,A24)
A26: Por prioridad | B26: Valor aprox. (COP)
A27: Obligatorio | B27: =SUMIFS('Lista Unificada'!$H$5:$H$104,'Lista Unificada'!$I$5:$I$104,A27)
A28: Recomendado | B28: =SUMIFS('Lista Unificada'!$H$5:$H$104,'Lista Unificada'!$I$5:$I$104,A28)
A29: Opcional | B29: =SUMIFS('Lista Unificada'!$H$5:$H$104,'Lista Unificada'!$I$5:$I$104,A29)
A31: Notas y supuestos:
A32: • Valores aproximados en COP (2026), referencia de distribuidores de dispositivos médicos en Colombia; variación esperada ±20-30%.
A33: • Prioridad orientativa según requisitos típicos de habilitación de consulta externa de medicina general (Resolución 3100 de 2019); verificar con la Secretaría de Salud.
A34: • Los equipos biomédicos requieren registro INVIMA, hoja de vida y plan de mantenimiento/calibración.
A35: • Cantidades pensadas para 1 consultorio y dotación inicial de consumibles (~1 mes).
A36: • Fuente 'Ambas' = ítem pedido por el Dr. Durán que ya estaba en la dotación básica (se unificó sin duplicar).
A37: • Según el Dr. Durán, el consultorio 1104 necesita la misma dotación que el 1105-01. Ajuste 'Consultorios a dotar' arriba.
A38: • Filas amarillas de 'Lista Unificada' = ítems adicionales; el total se actualiza solo.
